Workbook
Name Jobs: #REF!

Sheet FinalValues
A1: ENTITY | B1: DIMENSION:REGION | C1: DIMENSION:PROJECT | D1: DEPARTMENT | E1: TITLE
A2: Real Estate | B2: Bangalore | C2: Respective Parent Project Names | D2: Admin_Admin | E2: Trainee_Junior
A3: Contractual | B3: Mysore | D3: Admin_Dispatch | E3: Trainee_Assistant
A4: Glazing | B4: Trissur | D4: Admin_FacilityManagement | E4: Trainee
A5: Interior | B5: Cochin | D5: Admin_Maintenance | E5: Trainee_Senior
A6: CPD | B6: Calicut | D6: Audit_Audit | E6: Executive_Junior
A7: Mattress | B7: Trivandrum | D7: Audit_ConcurrentAudit | E7: Executive_Assistant
A8: Meter Cube | B8: Coimbatore | D8: Audit_InternalAudit | E8: Executive
A9: Corporate | B9: Chennai | D9: Audit_ManagementAudit | E9: Executive_Senior 1
B10: Hyderabad | D10: Audit_Procurement | E10: Executive_Senior 2
B11: Pune | D11: Audit_Technical | E11: ProjectEngineer 1
B12: Mumbai | D12: Corp_ChairmanEmeritusOffice | E12: ProjectEngineer 2
B13: Nagpur | D13: Corp_ChairmansOffice | E13: Manager_Assistant
B14: Ahmedabad | D14: Corp_Communication | E14: Manager_Deputy
B15: NCR | D15: Corp_Legal | E15: Manager
B16: Hosur | D16: Corp_Secreterial | E16: Manager_Senior
D17: Corp_Strategy | E17: GeneralManager_Assistant
D18: Corp_TrainingAndDevelopment | E18: GeneralManager_Deputy
D19: CRM_C3 | E19: GeneralManager
D20: CRM_CRM | E20: GeneralManager_Senior
D21: Design_Architecture | E21: VicePresident_Assistant
D22: Design_Design | E22: VicePresident
D23: Design_Electrical | E23: VicePresident_Senior
D24: Design_Envirionmental | E24: VicePresident_Executive
D25: Design_Fire&Safety | E25: Director_Managing
D26: Design_HVAC | E26: Director_Executive
D27: Design_Plumbing
D28: Design_Structural
D29: Finance_Billing
D30: Finance_Finance
D31: Finance_SalesFinance
D32: HR_HR
D33: IT_Infrastucture
D34: IT_IT
D35: IT_Process
D36: IT_Solution
D37: LandAndLegal_CRM
D38: LandAndLegal_Land
... D92: Stores_Stores

Sheet TITLE
A1: TITLEID | B1: Title | C1: Job | D1: Department | E1: Financial Dimension | F1: Entity
A2: Junior Architect | B2: Executive | C2: Architect
A3: Junior Architectural Technician | B3: Senior Executive | C3: Architectural Technician
A4: VC & MD | B4: VC & MD
A5: Deputy General Manager | B5: Deputy General Manager
A6: Senior Draftsman | B6: Senior Executive | C6: Draftsman
A7: Senior Design Engineer | B7: Senior Executive | C7: Design Engineer
A8: Assistant Manager | B8: Assistant Manager
A9: Chairman | B9: Chairman
A10: Chief Financial Officer | B10: Chief Financial Officer
A11: Company Secretary and Compliance Officer | B11: Company Secretary and Compliance Officer
A12: General Manager | B12: General Manager
A13: Trainee Structural Engineer | B13: Trainee | C13: Structural Engineer
A14: Interior Designer | B14: Senior Manager | C14: Interior Designer
A15: Senior Plant Operator | B15: Senior Executive | C15: Plant Operator
A16: Senior Production Supervisior | B16: Senior Manager | C16: Production Supervisor
A17: Senior Project Manager | B17: Senior Manager | C17: Project Management
A18: Senior Supervisor
A19: Senior Surveyor
A20: Structural Draftsman
A21: Project Engineer
A22: Executive Vice President
A23: Manager
A24: Trainee Assistant
A25: Senior Executive
A26: Supervisor
A27: Engineer
A28: Junior Structural Tecchnician
A29: Junior Executive
... A250: Managing Director

Sheet GrihaList
A1: JOBID | B1: Title | C1: Role | D1: Department | E1: Financial Dimension | F1: Entity | G1: Remark
A2: General Manager DTM | B2: GeneralManager | C2: DTM
A3: Engineer Value Engineering | B3: ProjectEngineer 1 | C3: Value Engineering
A4: Senior General Manager L & LP | B4: GeneralManager_Senior | C4: L&LP
A5: Senior Executive Sales Finance | B5: Executive_Senior 1 | D5: Finance_SalesFinance
A6: Senior Facility Management Executive
A7: Secretary Corp Communication
A8: Senior Foreman
A9: General Manager Proj
A10: Senior General Manager CPD
A11: Senior Granite Foreman
A12: Senior Housekeeping Supervisor
A13: Senior HR Executive
A14: Senior IT Executive
A15: Senior Land Purchase Executive
A16: Executive Sales Finance
A17: Data Entry Operator
... A994: Warehouse Executive

Sheet JOBS
A1: JOBID | B1: Title | C1: Job | D1: Department | E1: Financial Dimension | F1: Entity
A2: General Manager DTM | B2: General Manager | C2: DTM | D2: Project_TechnicianManagement
A3: Engineer Value Engineering | B3: Manager | C3: Value Engineering | D3: QST
A4: Senior General Manager L & LP | B4: Senior General Manager | C4: Legal Compliance | D4: L&LP
A5: Senior Executive Sales Finance | B5: Senior Executive | C5: Accountant - Receivable | D5: SalesFinance
A6: Senior Facility Management Executive | B6: Senior Executive | C6: Facility Maintenance | D6: FacilityManagement
A7: Secretary Corp Communication | B7: Assistant Manager | C7: Secretary | D7: CorpCommunication
A8: Senior Foreman | B8: Senior Executive | C8: Foreman | D8: Project_Delivery
A9: General Manager Proj | B9: General Manager | C9: Project Management | D9: Project_Delivery
A10: Senior General Manager CPD | B10: Senior General Manager | C10: CPD Supervisor | D10: BranchOffice | F10: CPD
A11: Senior Granite Foreman | B11: Senior Executive | C11: Granite Foreman | D11: Project_Delivery
A12: Senior Housekeeping Supervisor | B12: Senior Executive | C12: Housekeeping Supervisor | D12: FacilityManagement
A13: Senior HR Executive | B13: Senior Executive | C13: Recruitment | D13: HR
A14: Senior IT Executive | B14: Senior Executive | C14: Business Analyst | D14: IT_Solutions
A15: Senior Land Purchase Executive | B15: Senior Executive | C15: Land Purchase | D15: L&LP
A16: Executive Sales Finance | B16: Executive | C16: Accountant - Receivable | D16: SalesFinance
A17: Data Entry Operator | B17: Trainee | C17: Data Entry Operator
A18: Senior Maintenance manager | B18: Senior Manager | C18: Facility Maintenance | D18: FacilityManagement
A19: Senior Maintenance Supervisor | B19: Senior Supervisor | C19: Facility Maintenance | D19: FacilityManagement
A20: C R Executive Legal
A21: Senior Manager Audit
A22: Senior Manager Billing
A23: Senior Manager CRM
A24: Senior Manager Electrical
A25: Senior Manager Environmental
A26: Senior Manager Estimation
A27: Senior Manager Finance
A28: Senior Manager HR
A29: Senior Manager Legal
A30: Corp Communication Assistant
A31: Senior Manager Plumbing
... A158: Foreman
A159: Junior Land Purchase Executive | C159: Purchase Executive
A160: Fire & Safety Supervisor | C160: Safety Supervisor
A161: Safety Incharge | C161: Safety Incharge
A162: Assistant Manager Plumbing | C162: Manager Plumbing
A163: Junior Audit Executive | C163: Audit Executive
A164: Supervisor Fire Services | C164: Fire Services
A165: Executive Secretary | C165: Executive Secretary
A166: Production Engineer | C166: Production Engineer
...

Sheet DEPARTMENT
A1: Department / Sub Department | B1: Title | C1: Job | D1: Department | E1: Financial Dimension | F1: Entity | G1: NEW_DEPARTMENT
A2: ADMINISTRATION | D2: NA | G2: =VLOOKUP(D2,Department_Working!$B$2:$E$96,4,FALSE) -> NA_NA
A3: Administration | D3: Administration | F3: Corporate | G3: =VLOOKUP(D3,Department_Working!$B$2:$E$96,4,FALSE) -> Admin_Admin
A4: CHAIRMANS EMERITUS OFFICE | D4: NA | G4: =VLOOKUP(D4,Department_Working!$B$2:$E$96,4,FALSE) -> NA_NA
A5: Chairman Emeritus Office | D5: ChairmanEmeritusOffice | F5: Corporate | G5: =VLOOKUP(D5,Department_Working!$B$2:$E$96,4,FALSE) -> Corp_ChairmanEmeritusOffice
A6: CHAIRMANS OFFICE | D6: NA | G6: =VLOOKUP(D6,Department_Working!$B$2:$E$96,4,FALSE) -> NA_NA
A7: Chairmans Office | D7: ChairmansOffice | F7: Corporate | G7: =VLOOKUP(D7,Department_Working!$B$2:$E$96,4,FALSE) -> Corp_ChairmansOffice
A8: Land Strategy | D8: LandAndLegal_LandSrategy | F8: Corporate | G8: =VLOOKUP(D8,Department_Working!$B$2:$E$96,4,FALSE) -> LandAndLegal_LandSrategy
A9: CHENNAI REGIONAL OFFICE | D9: NA | G9: =VLOOKUP(D9,Department_Working!$B$2:$E$96,4,FALSE) -> NA_NA
A10: Administration - Chennai | D10: Administration | E10: REGION = Chennai | F10: Real Estate | G10: =VLOOKUP(D10,Department_Working!$B$2:$E$96,4,FALSE) -> Admin_Admin
A11: Architecture - Chennai | D11: Design_Architecture | E11: REGION = Chennai | F11: Real Estate | G11: =VLOOKUP(D11,Department_Working!$B$2:$E$96,4,FALSE) -> Design_Architecture
A12: Chennai Regional Office | D12: BranchOffice | E12: REGION = Chennai | F12: Real Estate | G12: =VLOOKUP(D12,Department_Working!$B$2:$E$96,4,FALSE) -> Office_Branch
A13: CRM - Chennai | D13: CRM | E13: REGION = Chennai | F13: Real Estate | G13: =VLOOKUP(D13,Department_Working!$B$2:$E$96,4,FALSE) -> CRM_CRM
A14: Finance - Chennai | D14: Finance | E14: REGION = Chennai | F14: Real Estate | G14: =VLOOKUP(D14,Department_Working!$B$2:$E$96,4,FALSE) -> Finance_Finance
A15: HR - Chennai | D15: HR | E15: REGION = Chennai | F15: Real Estate | G15: =VLOOKUP(D15,Department_Working!$B$2:$E$96,4,FALSE) -> HR_HR
A16: IT - Chennai | D16: IT | E16: REGION = Chennai | F16: Real Estate | G16: =VLOOKUP(D16,Department_Working!$B$2:$E$96,4,FALSE) -> IT_IT
A17: Land Purchase - Chennai | D17: LandAndLegal_LandPurchase | E17: REGION = Chennai | F17: Real Estate | G17: =VLOOKUP(D17,Department_Working!$B$2:$E$96,4,FALSE) -> LandAndLegal_LandPurchase
A18: Legal - Chennai | D18: LandAndLegal_Legal | E18: REGION = Chennai | F18: Real Estate | G18: =VLOOKUP(D18,Department_Working!$B$2:$E$96,4,FALSE) -> LandAndLegal_Legal
A19: Procurement - Chennai | D19: Procurement | E19: REGION = Chennai | F19: Real Estate | G19: =VLOOKUP(D19,Department_Working!$B$2:$E$96,4,FALSE) -> Procurement_Procurement
A20: Sales - Chennai | D20: Sales | E20: REGION = Chennai | F20: Real Estate | G20: =VLOOKUP(D20,Department_Working!$B$2:$E$96,4,FALSE) -> Sales_Sales
A21: COIMBATORE AREA OFFICE | D21: NA | G21: =VLOOKUP(D21,Department_Working!$B$2:$E$96,4,FALSE) -> NA_NA
A22: CRM - Coimbatore | D22: CRM | E22: REGION = Coimbatore | F22: Real Estate | G22: =VLOOKUP(D22,Department_Working!$B$2:$E$96,4,FALSE) -> CRM_CRM
A23: Finance - Coimbatore | D23: Finance | E23: REGION = Coimbatore | F23: Real Estate | G23: =VLOOKUP(D23,Department_Working!$B$2:$E$96,4,FALSE) -> Finance_Finance
A24: IT - Coimbatore | D24: IT | E24: REGION = Coimbatore | F24: Real Estate | G24: =VLOOKUP(D24,Department_Working!$B$2:$E$96,4,FALSE) -> IT_IT
A25: Legal - Coimbatore | D25: LandAndLegal_Legal | E25: REGION = Coimbatore | F25: Real Estate | G25: =VLOOKUP(D25,Department_Working!$B$2:$E$96,4,FALSE) -> LandAndLegal_Legal
A26: Sales - Coimbatore | D26: Sales | G26: =VLOOKUP(D26,Department_Working!$B$2:$E$96,4,FALSE) -> Sales_Sales
A27: CONCRETE PRODUCTS DIVISION | D27: NA | G27: =VLOOKUP(D27,Department_Working!$B$2:$E$96,4,FALSE) -> NA_NA
A28: Administration - CPD | D28: Administration | F28: CPD | G28: =VLOOKUP(D28,Department_Working!$B$2:$E$96,4,FALSE) -> Admin_Admin
A29: CEO - CPD | B29: CEO | D29: BranchOffice | F29: CPD | G29: =VLOOKUP(D29,Department_Working!$B$2:$E$96,4,FALSE) -> Office_Branch
A30: Dispatch - CPD | D30: Dispatch | F30: CPD | G30: =VLOOKUP(D30,Department_Working!$B$2:$E$96,4,FALSE) -> Admin_Dispatch
A31: GFRC - CPD | D31: GFRC | F31: CPD | G31: =VLOOKUP(D31,Department_Working!$B$2:$E$96,4,FALSE) -> Production_GFRC
A32: Maintenance - CPD | D32: Maintenance | F32: CPD | G32: =VLOOKUP(D32,Department_Working!$B$2:$E$96,4,FALSE) -> Admin_Maintenance
A33: Production - CPD | D33: Production | F33: CPD | G33: =VLOOKUP(D33,Department_Working!$B$2:$E$96,4,FALSE) -> Production_Production
A34: Quality - CPD | D34: QST_Quality | F34: CPD | G34: =VLOOKUP(D34,Department_Working!$B$2:$E$96,4,FALSE) -> QST_Quality
A35: Sales - CPD | D35: Sales | F35: CPD | G35: =VLOOKUP(D35,Department_Working!$B$2:$E$96,4,FALSE) -> Sales_Sales
A36: Stores - CPD | D36: Stores | F36: CPD | G36: =VLOOKUP(D36,Department_Working!$B$2:$E$96,4,FALSE) -> Stores_Stores
A37: CONTRACT PLUMBING | D37: NA | G37: =VLOOKUP(D37,Department_Working!$B$2:$E$96,4,FALSE) -> NA_NA
A38: Plumbing Design | D38: Plumbing_Design | F38: CONTRACT | G38: =VLOOKUP(D38,Department_Working!$B$2:$E$96,4,FALSE) -> M&E_PlumbingDesign
A39: Plumbing Execution | D39: Plumbing_Execution | F39: CONTRACT | G39: =VLOOKUP(D39,Department_Working!$B$2:$E$96,4,FALSE) -> M&E_PlumbingExecution
A40: CONTRACTS - INFOSYS | D40: NA | G40: =VLOOKUP(D40,Department_Working!$B$2:$E$96,4,FALSE) -> NA_NA
...

Sheet Department_Working
A1: SN | B1: OldName | C1: Primary | D1: Secondary | E1: New | H1: Row Labels
A2: 1 | B2: Administration | C2: Admin | D2: Admin | E2: =CONCATENATE(C2,"_",D2) -> Admin_Admin | H2: Admin_Admin
A3: 27 | B3: Dispatch | C3: Admin | D3: Dispatch | E3: =CONCATENATE(C3,"_",D3) -> Admin_Dispatch | H3: Admin_Dispatch
A4: 33 | B4: FacilityManagement | C4: Admin | D4: FacilityManagement | E4: =CONCATENATE(C4,"_",D4) -> Admin_FacilityManagement | H4: Admin_FacilityManagement
A5: 53 | B5: Maintenance | C5: Admin | D5: Maintenance | E5: =CONCATENATE(C5,"_",D5) -> Admin_Maintenance | H5: Admin_Maintenance
A6: 2 | B6: Audit | C6: Audit | D6: Audit | E6: =CONCATENATE(C6,"_",D6) -> Audit_Audit | H6: Audit_Audit
A7: 3 | B7: Audit_ConcurrentAudit | C7: Audit | D7: ConcurrentAudit | E7: =CONCATENATE(C7,"_",D7) -> Audit_ConcurrentAudit | H7: Audit_ConcurrentAudit
A8: 4 | B8: Audit_InternalAudit | C8: Audit | D8: InternalAudit | E8: =CONCATENATE(C8,"_",D8) -> Audit_InternalAudit | H8: Audit_InternalAudit
A9: 5 | B9: Audit_ManagementAudit | C9: Audit | D9: ManagementAudit | E9: =CONCATENATE(C9,"_",D9) -> Audit_ManagementAudit | H9: Audit_ManagementAudit
A10: 6 | B10: Audit_Procurement | C10: Audit | D10: Procurement | E10: =CONCATENATE(C10,"_",D10) -> Audit_Procurement | H10: Audit_Procurement
A11: 7 | B11: Audit_Technical | C11: Audit | D11: Technical | E11: =CONCATENATE(C11,"_",D11) -> Audit_Technical | H11: Audit_Technical
A12: 11 | B12: ChairmanEmeritusOffice | C12: Corp | D12: ChairmanEmeritusOffice | E12: =CONCATENATE(C12,"_",D12) -> Corp_ChairmanEmeritusOffice | H12: Corp_ChairmanEmeritusOffice
A13: 12 | B13: ChairmansOffice | C13: Corp | D13: ChairmansOffice | E13: =CONCATENATE(C13,"_",D13) -> Corp_ChairmansOffice | H13: Corp_ChairmansOffice
... A95: 91 | B95: Sales_Support | C95: Sales | D95: Support | E95: =CONCATENATE(C95,"_",D95) -> Sales_Support | H95: Grand Total
A96: 92 | B96: Stores | C96: Stores | D96: Stores | E96: =CONCATENATE(C96,"_",D96) -> Stores_Stores
